2025-03-05 22:43:53,848 - app.models - WARNING - Database connection attempt 1 failed: 'psycopg2.extensions.connection' object has no attribute 'dialect'
2025-03-05 22:43:53,848 - app.models - INFO - Retrying in 2 seconds...
2025-03-05 22:43:56,112 - app.models - WARNING - Database connection attempt 2 failed: 'psycopg2.extensions.connection' object has no attribute 'dialect'
2025-03-05 22:43:56,112 - app.models - INFO - Retrying in 4 seconds...
2025-03-05 22:44:00,398 - app.models - WARNING - Database connection attempt 3 failed: 'psycopg2.extensions.connection' object has no attribute 'dialect'
2025-03-05 22:44:00,398 - app.models - ERROR - Exceeded maximum retries (3) for database connection.
2025-03-05 22:44:00,398 - app.ai_analysis - WARNING - Failed to create AIAnalysis singleton: 'psycopg2.extensions.connection' object has no attribute 'dialect'. You'll need to create an instance manually.
2025-03-05 22:44:00,407 - __main__ - INFO - Starting bill fetch with limit=2, analyze=True
2025-03-05 22:44:00,691 - app.models - WARNING - Database connection attempt 1 failed: 'psycopg2.extensions.connection' object has no attribute 'dialect'
2025-03-05 22:44:00,692 - app.models - INFO - Retrying in 2 seconds...
2025-03-05 22:44:02,962 - app.models - WARNING - Database connection attempt 2 failed: 'psycopg2.extensions.connection' object has no attribute 'dialect'
2025-03-05 22:44:02,962 - app.models - INFO - Retrying in 4 seconds...
2025-03-05 22:44:07,246 - app.models - WARNING - Database connection attempt 3 failed: 'psycopg2.extensions.connection' object has no attribute 'dialect'
2025-03-05 22:44:07,246 - app.models - ERROR - Exceeded maximum retries (3) for database connection.
Traceback (most recent call last):
  File "/home/runner/workspace/scripts/fetch_initial_bills.py", line 172, in <module>
    fetch_and_analyze_bills(limit=args.limit, analyze=not args.no_analysis)
  File "/home/runner/workspace/scripts/fetch_initial_bills.py", line 42, in fetch_and_analyze_bills
    db_session_factory = init_db()
                         ^^^^^^^^^
  File "/home/runner/workspace/app/models.py", line 1460, in init_db
    with engine.connect() as connection:
         ^^^^^^^^^^^^^^^^
  File "/home/runner/workspace/.pythonlibs/lib/python3.12/site-packages/sqlalchemy/engine/base.py", line 3274, in connect
    return self._connection_cls(self)
           ^^^^^^^^^^^^^^^^^^^^^^^^^^
  File "/home/runner/workspace/.pythonlibs/lib/python3.12/site-packages/sqlalchemy/engine/base.py", line 146, in __init__
    self._dbapi_connection = engine.raw_connection()
                             ^^^^^^^^^^^^^^^^^^^^^^^
  File "/home/runner/workspace/.pythonlibs/lib/python3.12/site-packages/sqlalchemy/engine/base.py", line 3298, in raw_connection
    return self.pool.connect()
           ^^^^^^^^^^^^^^^^^^^
  File "/home/runner/workspace/.pythonlibs/lib/python3.12/site-packages/sqlalchemy/pool/base.py", line 449, in connect
    return _ConnectionFairy._checkout(self)
           ^^^^^^^^^^^^^^^^^^^^^^^^^^^^^^^^
  File "/home/runner/workspace/.pythonlibs/lib/python3.12/site-packages/sqlalchemy/pool/base.py", line 1263, in _checkout
    fairy = _ConnectionRecord.checkout(pool)
            ^^^^^^^^^^^^^^^^^^^^^^^^^^^^^^^^
  File "/home/runner/workspace/.pythonlibs/lib/python3.12/site-packages/sqlalchemy/pool/base.py", line 712, in checkout
    rec = pool._do_get()
          ^^^^^^^^^^^^^^
  File "/home/runner/workspace/.pythonlibs/lib/python3.12/site-packages/sqlalchemy/pool/impl.py", line 179, in _do_get
    with util.safe_reraise():
         ^^^^^^^^^^^^^^^^^^^
  File "/home/runner/workspace/.pythonlibs/lib/python3.12/site-packages/sqlalchemy/util/langhelpers.py", line 146, in __exit__
    raise exc_value.with_traceback(exc_tb)
  File "/home/runner/workspace/.pythonlibs/lib/python3.12/site-packages/sqlalchemy/pool/impl.py", line 177, in _do_get
    return self._create_connection()
           ^^^^^^^^^^^^^^^^^^^^^^^^^
  File "/home/runner/workspace/.pythonlibs/lib/python3.12/site-packages/sqlalchemy/pool/base.py", line 390, in _create_connection
    return _ConnectionRecord(self)
           ^^^^^^^^^^^^^^^^^^^^^^^
  File "/home/runner/workspace/.pythonlibs/lib/python3.12/site-packages/sqlalchemy/pool/base.py", line 674, in __init__
    self.__connect()
  File "/home/runner/workspace/.pythonlibs/lib/python3.12/site-packages/sqlalchemy/pool/base.py", line 914, in __connect
    )._exec_w_sync_on_first_run(self.dbapi_connection, self)
      ^^^^^^^^^^^^^^^^^^^^^^^^^^^^^^^^^^^^^^^^^^^^^^^^^^^^^^
  File "/home/runner/workspace/.pythonlibs/lib/python3.12/site-packages/sqlalchemy/event/attr.py", line 483, in _exec_w_sync_on_first_run
    self(*args, **kw)
  File "/home/runner/workspace/.pythonlibs/lib/python3.12/site-packages/sqlalchemy/event/attr.py", line 495, in __call__
    fn(*args, **kw)
  File "/home/runner/workspace/app/models.py", line 1406, in setup_postgres_extensions
    if conn.dialect.name == 'postgresql':
       ^^^^^^^^^^^^
AttributeError: 'psycopg2.extensions.connection' object has no attribute 'dialect'